Workbook

Sheet World Cup
E1: =Language!$E$121 -> World Cup 2026 in Canada/Mexico/USA | X1: hb/vers. 4.2.5 2026-04-10 | AV1: =X1 -> hb/vers. 4.2.5 2026-04-10
C2: =Language!$E$134 -> Pts. Goals | F2: =Language!$E$134 -> Pts. Goals | I2: =Language!$E$134 -> Pts. Goals | L2: =Language!$E$134 -> Pts. Goals | O2: =Language!$E$134 -> Pts. Goals | R2: =Language!$E$134 -> Pts. Goals | U2: =Language!$E$134 -> Pts. Goals | X2: =Language!$E$134 -> Pts. Goals | AA2: =Language!$E$134 -> Pts. Goals | AD2: =Language!$E$134 -> Pts. Goals | AG2: =Language!$E$134 -> Pts. Goals | AJ2: =Language!$E$134 -> Pts. Goals
B3: =CalcA!$D22 -> Mexico | C3: =" "&CalcA!$E22&" "&CalcA!$F22&Language!$E$197&CalcA!$G22 -> 9 6 - 1 | E3: =CalcB!$D22 -> Switzerland | F3: =" "&CalcB!$E22&" "&CalcB!$F22&Language!$E$197&CalcB!$G22 -> 9 6 - 1 | H3: =CalcC!$D22 -> Brazil | I3: =" "&CalcC!$E22&" "&CalcC!$F22&Language!$E$197&CalcC!$G22 -> 9 9 - 1 | K3: =CalcD!$D22 -> USA | L3: =" "&CalcD!$E22&" "&CalcD!$F22&Language!$E$197&CalcD!$G22 -> 7 5 - 2 | N3: =CalcE!$D22 -> Germany | O3: =" "&CalcE!$E22&" "&CalcE!$F22&Language!$E$197&CalcE!$G22 -> 9 12 - 1 | Q3: =CalcF!$D22 -> Netherlands | R3: =" "&CalcF!$E22&" "&CalcF!$F22&Language!$E$197&CalcF!$G22 -> 9 7 - 1 | T3: =CalcG!$D22 -> Belgium | U3: =" "&CalcG!$E22&" "&CalcG!$F22&Language!$E$197&CalcG!$G22 -> 9 9 - 3 | W3: =CalcH!$D22 -> Spain | X3: =" "&CalcH!$E22&" "&CalcH!$F22&Language!$E$197&CalcH!$G22 -> 9 12 - 2 | Z3: =CalcI!$D22 -> France | AA3: =" "&CalcI!$E22&" "&CalcI!$F22&Language!$E$197&CalcI!$G22 -> 9 10 - 3 | AC3: =CalcJ!$D22 -> Argentina | AD3: =" "&CalcJ!$E22&" "&CalcJ!$F22&Language!$E$197&CalcJ!$G22 -> 9 11 - 1 | AF3: =CalcK!$D22 -> Portugal | AG3: =" "&CalcK!$E22&" "&CalcK!$F22&Language!$E$197&CalcK!$G22 -> 9 12 - 1 | AI3: =CalcL!$D22 -> England | AJ3: =" "&CalcL!$E22&" "&CalcL!$F22&Language!$E$197&CalcL!$G22 -> 9 11 - 1
B4: =CalcA!$D23 -> Czech Rep. | C4: =" "&CalcA!$E23&" "&CalcA!$F23&Language!$E$197&CalcA!$G23 -> 4 2 - 2 | E4: =CalcB!$D23 -> Canada | F4: =" "&CalcB!$E23&" "&CalcB!$F23&Language!$E$197&CalcB!$G23 -> 6 5 - 2 | H4: =CalcC!$D23 -> Morocco | I4: =" "&CalcC!$E23&" "&CalcC!$F23&Language!$E$197&CalcC!$G23 -> 6 4 - 3 | K4: =CalcD!$D23 -> Turkey | L4: =" "&CalcD!$E23&" "&CalcD!$F23&Language!$E$197&CalcD!$G23 -> 5 5 - 3 | N4: =CalcE!$D23 -> Ecuador | O4: =" "&CalcE!$E23&" "&CalcE!$F23&Language!$E$197&CalcE!$G23 -> 6 6 - 4 | Q4: =CalcF!$D23 -> Japan | R4: =" "&CalcF!$E23&" "&CalcF!$F23&Language!$E$197&CalcF!$G23 -> 6 7 - 4 | T4: =CalcG!$D23 -> Egypt | U4: =" "&CalcG!$E23&" "&CalcG!$F23&Language!$E$197&CalcG!$G23 -> 6 6 - 3 | W4: =CalcH!$D23 -> Uruguay | X4: =" "&CalcH!$E23&" "&CalcH!$F23&Language!$E$197&CalcH!$G23 -> 6 6 - 4 | Z4: =CalcI!$D23 -> Norway | AA4: =" "&CalcI!$E23&" "&CalcI!$F23&Language!$E$197&CalcI!$G23 -> 6 5 - 4 | AC4: =CalcJ!$D23 -> Austria | AD4: =" "&CalcJ!$E23&" "&CalcJ!$F23&Language!$E$197&CalcJ!$G23 -> 6 3 - 3 | AF4: =CalcK!$D23 -> Colombia | AG4: =" "&CalcK!$E23&" "&CalcK!$F23&Language!$E$197&CalcK!$G23 -> 6 4 - 3 | AI4: =CalcL!$D23 -> Croatia | AJ4: =" "&CalcL!$E23&" "&CalcL!$F23&Language!$E$197&CalcL!$G23 -> 6 6 - 3
B5: =CalcA!$D24 -> Rep. of Korea | C5: =" "&CalcA!$E24&" "&CalcA!$F24&Language!$E$197&CalcA!$G24 -> 2 2 - 4 | E5: =CalcB!$D24 -> Qatar | F5: =" "&CalcB!$E24&" "&CalcB!$F24&Language!$E$197&CalcB!$G24 -> 3 3 - 5 | H5: =CalcC!$D24 -> Scotland | I5: =" "&CalcC!$E24&" "&CalcC!$F24&Language!$E$197&CalcC!$G24 -> 3 4 - 4 | K5: =CalcD!$D24 -> Australia | L5: =" "&CalcD!$E24&" "&CalcD!$F24&Language!$E$197&CalcD!$G24 -> 2 1 - 2 | N5: =CalcE!$D24 -> Ivory Coast | O5: =" "&CalcE!$E24&" "&CalcE!$F24&Language!$E$197&CalcE!$G24 -> 1 0 - 6 | Q5: =CalcF!$D24 -> Sweden | R5: =" "&CalcF!$E24&" "&CalcF!$F24&Language!$E$197&CalcF!$G24 -> 3 3 - 5 | T5: =CalcG!$D24 -> New Zealand | U5: =" "&CalcG!$E24&" "&CalcG!$F24&Language!$E$197&CalcG!$G24 -> 1 2 - 6 | W5: =CalcH!$D24 -> Saudi Arabia | X5: =" "&CalcH!$E24&" "&CalcH!$F24&Language!$E$197&CalcH!$G24 -> 3 6 - 7 | Z5: =CalcI!$D24 -> Senegal | AA5: =" "&CalcI!$E24&" "&CalcI!$F24&Language!$E$197&CalcI!$G24 -> 3 5 - 6 | AC5: =CalcJ!$D24 -> Algeria | AD5: =" "&CalcJ!$E24&" "&CalcJ!$F24&Language!$E$197&CalcJ!$G24 -> 1 1 - 6 | AF5: =CalcK!$D24 -> Uzbekistan | AG5: =" "&CalcK!$E24&" "&CalcK!$F24&Language!$E$197&CalcK!$G24 -> 1 2 - 7 | AI5: =CalcL!$D24 -> Ghana | AJ5: =" "&CalcL!$E24&" "&CalcL!$F24&Language!$E$197&CalcL!$G24 -> 3 1 - 6
B6: =CalcA!$D25 -> South Africa | C6: =" "&CalcA!$E25&" "&CalcA!$F25&Language!$E$197&CalcA!$G25 -> 1 0 - 3 | E6: =CalcB!$D25 -> Bosnia/Herzeg. | F6: =" "&CalcB!$E25&" "&CalcB!$F25&Language!$E$197&CalcB!$G25 -> 0 2 - 8 | H6: =CalcC!$D25 -> Haiti | I6: =" "&CalcC!$E25&" "&CalcC!$F25&Language!$E$197&CalcC!$G25 -> 0 1 - 10 | K6: =CalcD!$D25 -> Paraguay | L6: =" "&CalcD!$E25&" "&CalcD!$F25&Language!$E$197&CalcD!$G25 -> 1 0 - 4 | N6: =CalcE!$D25 -> Curaçao | O6: =" "&CalcE!$E25&" "&CalcE!$F25&Language!$E$197&CalcE!$G25 -> 1 1 - 8 | Q6: =CalcF!$D25 -> Tunisia | R6: =" "&CalcF!$E25&" "&CalcF!$F25&Language!$E$197&CalcF!$G25 -> 0 0 - 7 | T6: =CalcG!$D25 -> IR Iran | U6: =" "&CalcG!$E25&" "&CalcG!$F25&Language!$E$197&CalcG!$G25 -> 1 1 - 6 | W6: =CalcH!$D25 -> Cape Verde | X6: =" "&CalcH!$E25&" "&CalcH!$F25&Language!$E$197&CalcH!$G25 -> 0 1 - 12 | Z6: =CalcI!$D25 -> Iraq | AA6: =" "&CalcI!$E25&" "&CalcI!$F25&Language!$E$197&CalcI!$G25 -> 0 0 - 7 | AC6: =CalcJ!$D25 -> Jordan | AD6: =" "&CalcJ!$E25&" "&CalcJ!$F25&Language!$E$197&CalcJ!$G25 -> 1 1 - 6 | AF6: =CalcK!$D25 -> DR Congo | AG6: =" "&CalcK!$E25&" "&CalcK!$F25&Language!$E$197&CalcK!$G25 -> 1 2 - 9 | AI6: =CalcL!$D25 -> Panama | AJ6: =" "&CalcL!$E25&" "&CalcL!$F25&Language!$E$197&CalcL!$G25 -> 0 0 - 8
B7: =IF(Distinctness!$G$17=0,"",IF(Distinctness!$D$4>0,Distinctness!$J$4,Distinctness!$J$5)) -> Groups with fair play valuation: J. | Z7: =B7 -> Groups with fair play valuation: J. | AZ7: =DailySchedule!$N7 -> England
B8: =IF(CalcA!$AU$14,"•","") | E8: =IF(CalcB!$AU$14,"•","") | H8: =IF(CalcC!$AU$14,"•","") | K8: =IF(CalcD!$AU$14,"•","") | N8: =IF(CalcE!$AU$14,"•","") | Q8: =IF(CalcF!$AU$14,"•","") | T8: =IF(CalcG!$AU$14,"•","") | W8: =IF(CalcH!$AU$14,"•","") | Z8: =IF(CalcI!$AU$14,"•","") | AC8: =IF(CalcJ!$AU$14,"•","") -> • | AF8: =IF(CalcK!$AU$14,"•","") | AI8: =IF(CalcL!$AU$14,"•","") | AZ8: =DailySchedule!$N8 -> USA
B9: =Language!$E$130&" A" -> Group A | E9: =Language!$E$130&" B" -> Group B | H9: =Language!$E$130&" C" -> Group C | K9: =Language!$E$130&" D" -> Group D | N9: =Language!$E$130&" E" -> Group E | Q9: =Language!$E$130&" F" -> Group F | T9: =Language!$E$130&" G" -> Group G | W9: =Language!$E$130&" H" -> Group H | Z9: =Language!$E$130&" I" -> Group I | AC9: =Language!$E$130&" J" -> Group J | AF9: =Language!$E$130&" K" -> Group K | AI9: =Language!$E$130&" L" -> Group L | AZ9: =DailySchedule!$N9 -> Canada
AZ10: =DailySchedule!$N10 -> Mexico
A11: 1 | B11: =VLOOKUP(A11,Matches!$B$4:$K$113,7,0) -> Mexico City | D11: 3 | E11: =VLOOKUP(D11,Matches!$B$4:$K$113,7,0) -> Toronto | G11: 7 | H11: =VLOOKUP(G11,Matches!$B$4:$K$113,7,0) -> New York/New Jersey | J11: 4 | K11: =VLOOKUP(J11,Matches!$B$4:$K$113,7,0) -> Los Angeles | M11: 10 | N11: =VLOOKUP(M11,Matches!$B$4:$K$113,7,0) -> Houston | P11: 11 | Q11: =VLOOKUP(P11,Matches!$B$4:$K$113,7,0) -> Dallas | S11: 16 | T11: =VLOOKUP(S11,Matches!$B$4:$K$113,7,0) -> Seattle | V11: 14 | W11: =VLOOKUP(V11,Matches!$B$4:$K$113,7,0) -> Atlanta | Y11: 17 | Z11: =VLOOKUP(Y11,Matches!$B$4:$K$113,7,0) -> New York/New Jersey | AB11: 19 | AC11: =VLOOKUP(AB11,Matches!$B$4:$K$113,7,0) -> Kansas City | AE11: 23 | AF11: =VLOOKUP(AE11,Matches!$B$4:$K$113,7,0) -> Houston | AH11: 22 | AI11: =VLOOKUP(AH11,Matches!$B$4:$K$113,7,0) -> Dallas
B12: =VLOOKUP(A11,Matches!$B$4:$K$113,5,0) -> 46184.875 | E12: =VLOOKUP(D11,Matches!$B$4:$K$113,5,0) -> 46185.875 | H12: =VLOOKUP(G11,Matches!$B$4:$K$113,5,0) -> 46187 | K12: =VLOOKUP(J11,Matches!$B$4:$K$113,5,0) -> 46186.125 | N12: =VLOOKUP(M11,Matches!$B$4:$K$113,5,0) -> 46187.792 | Q12: =VLOOKUP(P11,Matches!$B$4:$K$113,5,0) -> 46187.917 | T12: =VLOOKUP(S11,Matches!$B$4:$K$113,5,0) -> 46188.875 | W12: =VLOOKUP(V11,Matches!$B$4:$K$113,5,0) -> 46188.75 | Z12: =VLOOKUP(Y11,Matches!$B$4:$K$113,5,0) -> 46189.875 | AC12: =VLOOKUP(AB11,Matches!$B$4:$K$113,5,0) -> 46190.125 | AF12: =VLOOKUP(AE11,Matches!$B$4:$K$113,5,0) -> 46190.792 | AI12: =VLOOKUP(AH11,Matches!$B$4:$K$113,5,0) -> 46190.917
B13: =VLOOKUP(A11,Matches!$B$4:$K$113,8,0) -> Mexico | C13: =VLOOKUP(A11,Matches!$B$4:$K$113,9,0) -> South Africa | E13: =VLOOKUP(D11,Matches!$B$4:$K$113,8,0) -> Canada | F13: =VLOOKUP(D11,Matches!$B$4:$K$113,9,0) -> Bosnia/Herzeg. | H13: =VLOOKUP(G11,Matches!$B$4:$K$113,8,0) -> Brazil | I13: =VLOOKUP(G11,Matches!$B$4:$K$113,9,0) -> Morocco | K13: =VLOOKUP(J11,Matches!$B$4:$K$113,8,0) -> USA | L13: =VLOOKUP(J11,Matches!$B$4:$K$113,9,0) -> Paraguay | N13: =VLOOKUP(M11,Matches!$B$4:$K$113,8,0) -> Germany | O13: =VLOOKUP(M11,Matches!$B$4:$K$113,9,0) -> Curaçao | Q13: =VLOOKUP(P11,Matches!$B$4:$K$113,8,0) -> Netherlands | R13: =VLOOKUP(P11,Matches!$B$4:$K$113,9,0) -> Japan | T13: =VLOOKUP(S11,Matches!$B$4:$K$113,8,0) -> Belgium | U13: =VLOOKUP(S11,Matches!$B$4:$K$113,9,0) -> Egypt | W13: =VLOOKUP(V11,Matches!$B$4:$K$113,8,0) -> Spain | X13: =VLOOKUP(V11,Matches!$B$4:$K$113,9,0) -> Cape Verde | Z13: =VLOOKUP(Y11,Matches!$B$4:$K$113,8,0) -> France | AA13: =VLOOKUP(Y11,Matches!$B$4:$K$113,9,0) -> Senegal | AC13: =VLOOKUP(AB11,Matches!$B$4:$K$113,8,0) -> Argentina | AD13: =VLOOKUP(AB11,Matches!$B$4:$K$113,9,0) -> Algeria | AF13: =VLOOKUP(AE11,Matches!$B$4:$K$113,8,0) -> Portugal | AG13: =VLOOKUP(AE11,Matches!$B$4:$K$113,9,0) -> DR Congo | AI13: =VLOOKUP(AH11,Matches!$B$4:$K$113,8,0) -> England | AJ13: =VLOOKUP(AH11,Matches!$B$4:$K$113,9,0) -> Croatia
B14: 2 | C14: 0 | E14: 3 | F14: 1 | H14: 2 | I14: 0 | K14: 2 | L14: 0 | N14: 5 | O14: 0 | Q14: 2 | R14: 1 | T14: 3 | U14: 2 | W14: 5 | X14: 0 | Z14: 4 | AA14: 2 | AC14: 4 | AD14: 0 | AF14: 5 | AG14: 0 | AI14: 3 | AJ14: 1
A16: 2 | B16: =VLOOKUP(A16,Matches!$B$4:$K$113,7,0) -> Guadalajara | D16: 8 | E16: =VLOOKUP(D16,Matches!$B$4:$K$113,7,0) -> San Francisco Bay Area | G16: 5 | H16: =VLOOKUP(G16,Matches!$B$4:$K$113,7,0) -> Boston | J16: 6 | K16: =VLOOKUP(J16,Matches!$B$4:$K$113,7,0) -> Vancouver | M16: 9 | N16: =VLOOKUP(M16,Matches!$B$4:$K$113,7,0) -> Philadelphia | P16: 12 | Q16: =VLOOKUP(P16,Matches!$B$4:$K$113,7,0) -> Monterrey | S16: 15 | T16: =VLOOKUP(S16,Matches!$B$4:$K$113,7,0) -> Los Angeles | V16: 13 | W16: =VLOOKUP(V16,Matches!$B$4:$K$113,7,0) -> Miami | Y16: 18 | Z16: =VLOOKUP(Y16,Matches!$B$4:$K$113,7,0) -> Boston | AB16: 20 | AC16: =VLOOKUP(AB16,Matches!$B$4:$K$113,7,0) -> San Francisco Bay Area | AE16: 24 | AF16: =VLOOKUP(AE16,Matches!$B$4:$K$113,7,0) -> Mexico City | AH16: 21 | AI16: =VLOOKUP(AH16,Matches!$B$4:$K$113,7,0) -> Toronto
B17: =VLOOKUP(A16,Matches!$B$4:$K$113,5,0) -> 46185.167 | E17: =VLOOKUP(D16,Matches!$B$4:$K$113,5,0) -> 46186.875 | H17: =VLOOKUP(G16,Matches!$B$4:$K$113,5,0) -> 46187.125 | K17: =VLOOKUP(J16,Matches!$B$4:$K$113,5,0) -> 46187.25 | N17: =VLOOKUP(M16,Matches!$B$4:$K$113,5,0) -> 46188.042 | Q17: =VLOOKUP(P16,Matches!$B$4:$K$113,5,0) -> 46188.167 | T17: =VLOOKUP(S16,Matches!$B$4:$K$113,5,0) -> 46189.125 | W17: =VLOOKUP(V16,Matches!$B$4:$K$113,5,0) -> 46189 | Z17: =VLOOKUP(Y16,Matches!$B$4:$K$113,5,0) -> 46190 | AC17: =VLOOKUP(AB16,Matches!$B$4:$K$113,5,0) -> 46190.25 | AF17: =VLOOKUP(AE16,Matches!$B$4:$K$113,5,0) -> 46191.167 | AI17: =VLOOKUP(AH16,Matches!$B$4:$K$113,5,0) -> 46191.042
B18: =VLOOKUP(A16,Matches!$B$4:$K$113,8,0) -> Rep. of Korea | C18: =VLOOKUP(A16,Matches!$B$4:$K$113,9,0) -> Czech Rep. | E18: =VLOOKUP(D16,Matches!$B$4:$K$113,8,0) -> Qatar | F18: =VLOOKUP(D16,Matches!$B$4:$K$113,9,0) -> Switzerland | H18: =VLOOKUP(G16,Matches!$B$4:$K$113,8,0) -> Haiti | I18: =VLOOKUP(G16,Matches!$B$4:$K$113,9,0) -> Scotland | K18: =VLOOKUP(J16,Matches!$B$4:$K$113,8,0) -> Australia | L18: =VLOOKUP(J16,Matches!$B$4:$K$113,9,0) -> Turkey | N18: =VLOOKUP(M16,Matches!$B$4:$K$113,8,0) -> Ivory Coast | O18: =VLOOKUP(M16,Matches!$B$4:$K$113,9,0) -> Ecuador | Q18: =VLOOKUP(P16,Matches!$B$4:$K$113,8,0) -> Sweden | R18: =VLOOKUP(P16,Matches!$B$4:$K$113,9,0) -> Tunisia | T18: =VLOOKUP(S16,Matches!$B$4:$K$113,8,0) -> IR Iran | U18: =VLOOKUP(S16,Matches!$B$4:$K$113,9,0) -> New Zealand | W18: =VLOOKUP(V16,Matches!$B$4:$K$113,8,0) -> Saudi Arabia | X18: =VLOOKUP(V16,Matches!$B$4:$K$113,9,0) -> Uruguay | Z18: =VLOOKUP(Y16,Matches!$B$4:$K$113,8,0) -> Iraq | AA18: =VLOOKUP(Y16,Matches!$B$4:$K$113,9,0) -> Norway | AC18: =VLOOKUP(AB16,Matches!$B$4:$K$113,8,0) -> Austria | AD18: =VLOOKUP(AB16,Matches!$B$4:$K$113,9,0) -> Jordan | AF18: =VLOOKUP(AE16,Matches!$B$4:$K$113,8,0) -> Uzbekistan | AG18: =VLOOKUP(AE16,Matches!$B$4:$K$113,9,0) -> Colombia | AI18: =VLOOKUP(AH16,Matches!$B$4:$K$113,8,0) -> Ghana | AJ18: =VLOOKUP(AH16,Matches!$B$4:$K$113,9,0) -> Panama
B19: 1 | C19: 1 | E19: 1 | F19: 2 | H19: 0 | I19: 3 | K19: 1 | L19: 1 | N19: 0 | O19: 2 | Q19: 1 | R19: 0 | T19: 1 | U19: 1 | W19: 1 | X19: 2 | Z19: 0 | AA19: 2 | AC19: 1 | AD19: 0 | AF19: 0 | AG19: 1 | AI19: 1 | AJ19: 0
A21: 25 | B21: =VLOOKUP(A21,Matches!$B$4:$K$113,7,0) -> Atlanta | D21: 26 | E21: =VLOOKUP(D21,Matches!$B$4:$K$113,7,0) -> Los Angeles | G21: 30 | H21: =VLOOKUP(G21,Matches!$B$4:$K$113,7,0) -> Boston | J21: 32 | K21: =VLOOKUP(J21,Matches!$B$4:$K$113,7,0) -> Seattle | M21: 33 | N21: =VLOOKUP(M21,Matches!$B$4:$K$113,7,0) -> Toronto | P21: 35 | Q21: =VLOOKUP(P21,Matches!$B$4:$K$113,7,0) -> Houston | S21: 39 | T21: =VLOOKUP(S21,Matches!$B$4:$K$113,7,0) -> Los Angeles | V21: 38 | W21: =VLOOKUP(V21,Matches!$B$4:$K$113,7,0) -> Atlanta | Y21: 42 | Z21: =VLOOKUP(Y21,Matches!$B$4:$K$113,7,0) -> Philadelphia | AB21: 43 | AC21: =VLOOKUP(AB21,Matches!$B$4:$K$113,7,0) -> Dallas | AE21: 47 | AF21: =VLOOKUP(AE21,Matches!$B$4:$K$113,7,0) -> Houston | AH21: 45 | AI21: =VLOOKUP(AH21,Matches!$B$4:$K$113,7,0) -> Boston
B22: =VLOOKUP(A21,Matches!$B$4:$K$113,5,0) -> 46191.75 | E22: =VLOOKUP(D21,Matches!$B$4:$K$113,5,0) -> 46191.875 | H22: =VLOOKUP(G21,Matches!$B$4:$K$113,5,0) -> 46193 | K22: =VLOOKUP(J21,Matches!$B$4:$K$113,5,0) -> 46192.875 | N22: =VLOOKUP(M21,Matches!$B$4:$K$113,5,0) -> 46193.917 | Q22: =VLOOKUP(P21,Matches!$B$4:$K$113,5,0) -> 46193.792 | T22: =VLOOKUP(S21,Matches!$B$4:$K$113,5,0) -> 46194.875 | W22: =VLOOKUP(V21,Matches!$B$4:$K$113,5,0) -> 46194.75 | Z22: =VLOOKUP(Y21,Matches!$B$4:$K$113,5,0) -> 46195.958 | AC22: =VLOOKUP(AB21,Matches!$B$4:$K$113,5,0) -> 46195.792 | AF22: =VLOOKUP(AE21,Matches!$B$4:$K$113,5,0) -> 46196.792 | AI22: =VLOOKUP(AH21,Matches!$B$4:$K$113,5,0) -> 46196.917
B23: =VLOOKUP(A21,Matches!$B$4:$K$113,8,0) -> Czech Rep. | C23: =VLOOKUP(A21,Matches!$B$4:$K$113,9,0) -> South Africa | E23: =VLOOKUP(D21,Matches!$B$4:$K$113,8,0) -> Switzerland | F23: =VLOOKUP(D21,Matches!$B$4:$K$113,9,0) -> Bosnia/Herzeg. | H23: =VLOOKUP(G21,Matches!$B$4:$K$113,8,0) -> Scotland | I23: =VLOOKUP(G21,Matches!$B$4:$K$113,9,0) -> Morocco | K23: =VLOOKUP(J21,Matches!$B$4:$K$113,8,0) -> USA | L23: =VLOOKUP(J21,Matches!$B$4:$K$113,9,0) -> Australia | N23: =VLOOKUP(M21,Matches!$B$4:$K$113,8,0) -> Germany | O23: =VLOOKUP(M21,Matches!$B$4:$K$113,9,0) -> Ivory Coast | Q23: =VLOOKUP(P21,Matches!$B$4:$K$113,8,0) -> Netherlands | R23: =VLOOKUP(P21,Matches!$B$4:$K$113,9,0) -> Sweden | T23: =VLOOKUP(S21,Matches!$B$4:$K$113,8,0) -> Belgium | U23: =VLOOKUP(S21,Matches!$B$4:$K$113,9,0) -> IR Iran | W23: =VLOOKUP(V21,Matches!$B$4:$K$113,8,0) -> Spain | X23: =VLOOKUP(V21,Matches!$B$4:$K$113,9,0) -> Saudi Arabia | Z23: =VLOOKUP(Y21,Matches!$B$4:$K$113,8,0) -> France | AA23: =VLOOKUP(Y21,Matches!$B$4:$K$113,9,0) -> Iraq | AC23: =VLOOKUP(AB21,Matches!$B$4:$K$113,8,0) -> Argentina | AD23: =VLOOKUP(AB21,Matches!$B$4:$K$113,9,0) -> Austria | AF23: =VLOOKUP(AE21,Matches!$B$4:$K$113,8,0) -> Portugal | AG23: =VLOOKUP(AE21,Matches!$B$4:$K$113,9,0) -> Uzbekistan | AI23: =VLOOKUP(AH21,Matches!$B$4:$K$113,8,0) -> England | AJ23: =VLOOKUP(AH21,Matches!$B$4:$K$113,9,0) -> Ghana
B24: 1 | C24: 0 | E24: 3 | F24: 0 | H24: 0 | I24: 1 | K24: 1 | L24: 0 | N24: 4 | O24: 0 | Q24: 2 | R24: 0 | T24: 3 | U24: 0 | W24: 4 | X24: 1 | Z24: 3 | AA24: 0 | AC24: 3 | AD24: 1 | AF24: 4 | AG24: 0 | AI24: 4 | AJ24: 0
A26: 28 | B26: =VLOOKUP(A26,Matches!$B$4:$K$113,7,0) -> Guadalajara | D26: 27 | E26: =VLOOKUP(D26,Matches!$B$4:$K$113,7,0) -> Vancouver | G26: 29 | H26: =VLOOKUP(G26,Matches!$B$4:$K$113,7,0) -> Philadelphia | J26: 31 | K26: =VLOOKUP(J26,Matches!$B$4:$K$113,7,0) -> San Francisco Bay Area | M26: 34 | N26: =VLOOKUP(M26,Matches!$B$4:$K$113,7,0) -> Kansas City | P26: 36 | Q26: =VLOOKUP(P26,Matches!$B$4:$K$113,7,0) -> Monterrey | S26: 40 | T26: =VLOOKUP(S26,Matches!$B$4:$K$113,7,0) -> Vancouver | V26: 37 | W26: =VLOOKUP(V26,Matches!$B$4:$K$113,7,0) -> Miami | Y26: 41 | Z26: =VLOOKUP(Y26,Matches!$B$4:$K$113,7,0) -> New York/New Jersey | AB26: 44 | AC26: =VLOOKUP(AB26,Matches!$B$4:$K$113,7,0) -> San Francisco Bay Area | AE26: 48 | AF26: =VLOOKUP(AE26,Matches!$B$4:$K$113,7,0) -> Guadalajara | AH26: 46 | AI26: =VLOOKUP(AH26,Matches!$B$4:$K$113,7,0) -> Toronto
B27: =VLOOKUP(A26,Matches!$B$4:$K$113,5,0) -> 46192.125 | E27: =VLOOKUP(D26,Matches!$B$4:$K$113,5,0) -> 46192 | H27: =VLOOKUP(G26,Matches!$B$4:$K$113,5,0) -> 46193.104 | K27: =VLOOKUP(J26,Matches!$B$4:$K$113,5,0) -> 46193.208 | N27: =VLOOKUP(M26,Matches!$B$4:$K$113,5,0) -> 46194.083 | Q27: =VLOOKUP(P26,Matches!$B$4:$K$113,5,0) -> 46194.25 | T27: =VLOOKUP(S26,Matches!$B$4:$K$113,5,0) -> 46195.125 | W27: =VLOOKUP(V26,Matches!$B$4:$K$113,5,0) -> 46195 | Z27: =VLOOKUP(Y26,Matches!$B$4:$K$113,5,0) -> 46196.083 | AC27: =VLOOKUP(AB26,Matches!$B$4:$K$113,5,0) -> 46196.208 | AF27: =VLOOKUP(AE26,Matches!$B$4:$K$113,5,0) -> 46197.167 | AI27: =VLOOKUP(AH26,Matches!$B$4:$K$113,5,0) -> 46197.042
B28: =VLOOKUP(A26,Matches!$B$4:$K$113,8,0) -> Mexico | C28: =VLOOKUP(A26,Matches!$B$4:$K$113,9,0) -> Rep. of Korea | E28: =VLOOKUP(D26,Matches!$B$4:$K$113,8,0) -> Canada | F28: =VLOOKUP(D26,Matches!$B$4:$K$113,9,0) -> Qatar | H28: =VLOOKUP(G26,Matches!$B$4:$K$113,8,0) -> Brazil | I28: =VLOOKUP(G26,Matches!$B$4:$K$113,9,0) -> Haiti | K28: =VLOOKUP(J26,Matches!$B$4:$K$113,8,0) -> Turkey | L28: =VLOOKUP(J26,Matches!$B$4:$K$113,9,0) -> Paraguay | N28: =VLOOKUP(M26,Matches!$B$4:$K$113,8,0) -> Ecuador | O28: =VLOOKUP(M26,Matches!$B$4:$K$113,9,0) -> Curaçao | Q28: =VLOOKUP(P26,Matches!$B$4:$K$113,8,0) -> Tunisia | R28: =VLOOKUP(P26,Matches!$B$4:$K$113,9,0) -> Japan | T28: =VLOOKUP(S26,Matches!$B$4:$K$113,8,0) -> New Zealand | U28: =VLOOKUP(S26,Matches!$B$4:$K$113,9,0) -> Egypt | W28: =VLOOKUP(V26,Matches!$B$4:$K$113,8,0) -> Uruguay | X28: =VLOOKUP(V26,Matches!$B$4:$K$113,9,0) -> Cape Verde | Z28: =VLOOKUP(Y26,Matches!$B$4:$K$113,8,0) -> Norway | AA28: =VLOOKUP(Y26,Matches!$B$4:$K$113,9,0) -> Senegal | AC28: =VLOOKUP(AB26,Matches!$B$4:$K$113,8,0) -> Jordan | AD28: =VLOOKUP(AB26,Matches!$B$4:$K$113,9,0) -> Algeria | AF28: =VLOOKUP(AE26,Matches!$B$4:$K$113,8,0) -> Colombia | AG28: =VLOOKUP(AE26,Matches!$B$4:$K$113,9,0) -> DR Congo | AI28: =VLOOKUP(AH26,Matches!$B$4:$K$113,8,0) -> Panama | AJ28: =VLOOKUP(AH26,Matches!$B$4:$K$113,9,0) -> Croatia
B29: 3 | C29: 1 | E29: 2 | F29: 0 | H29: 4 | I29: 0 | K29: 2 | L29: 0 | N29: 3 | O29: 1 | Q29: 0 | R29: 3 | T29: 0 | U29: 2 | W29: 3 | X29: 0 | Z29: 2 | AA29: 1 | AC29: 1 | AD29: 1 | AF29: 2 | AG29: 0 | AI29: 0 | AJ29: 3
AL30: =IF(ThirdPlaced!$I$33,"•","")
A31: 53 | B31: =VLOOKUP(A31,Matches!$B$4:$K$113,7,0) -> Mexico City | D31: 51 | E31: =VLOOKUP(D31,Matches!$B$4:$K$113,7,0) -> Vancouver | G31: 49 | H31: =VLOOKUP(G31,Matches!$B$4:$K$113,7,0) -> Miami | J31: 59 | K31: =VLOOKUP(J31,Matches!$B$4:$K$113,7,0) -> Los Angeles | M31: 55 | N31: =VLOOKUP(M31,Matches!$B$4:$K$113,7,0) -> Philadelphia | P31: 57 | Q31: =VLOOKUP(P31,Matches!$B$4:$K$113,7,0) -> Dallas | S31: 63 | T31: =VLOOKUP(S31,Matches!$B$4:$K$113,7,0) -> Seattle | V31: 65 | W31: =VLOOKUP(V31,Matches!$B$4:$K$113,7,0) -> Houston | Y31: 61 | Z31: =VLOOKUP(Y31,Matches!$B$4:$K$113,7,0) -> Boston | AB31: 69 | AC31: =VLOOKUP(AB31,Matches!$B$4:$K$113,7,0) -> Kansas City | AE31: 71 | AF31: =VLOOKUP(AE31,Matches!$B$4:$K$113,7,0) -> Miami | AH31: 67 | AI31: =VLOOKUP(AH31,Matches!$B$4:$K$113,7,0) -> New York/New Jersey | AL31: =Language!$E$180 -> Third in the group | AN31: =Language!$E$181 -> Grp
B32: =VLOOKUP(A31,Matches!$B$4:$K$113,5,0) -> 46198.125 | E32: =VLOOKUP(D31,Matches!$B$4:$K$113,5,0) -> 46197.875 | H32: =VLOOKUP(G31,Matches!$B$4:$K$113,5,0) -> 46198 | K32: =VLOOKUP(J31,Matches!$B$4:$K$113,5,0) -> 46199.167 | N32: =VLOOKUP(M31,Matches!$B$4:$K$113,5,0) -> 46198.917 | Q32: =VLOOKUP(P31,Matches!$B$4:$K$113,5,0) -> 46199.042 | T32: =VLOOKUP(S31,Matches!$B$4:$K$113,5,0) -> 46200.208 | W32: =VLOOKUP(V31,Matches!$B$4:$K$113,5,0) -> 46200.083 | Z32: =VLOOKUP(Y31,Matches!$B$4:$K$113,5,0) -> 46199.875 | AC32: =VLOOKUP(AB31,Matches!$B$4:$K$113,5,0) -> 46201.167 | AF32: =VLOOKUP(AE31,Matches!$B$4:$K$113,5,0) -> 46201.062 | AI32: =VLOOKUP(AH31,Matches!$B$4:$K$113,5,0) -> 46200.958 | AL32: =IF(OR(ThirdPlaced!$D17>0,ThirdPlaced!$G17>0),ThirdPlaced!$C17,"") -> Scotland | AM32: =IF(AL32<>""," "&ThirdPlaced!$D17&" "&ThirdPlaced!$F17&Language!$E$197&ThirdPlaced!$G17,"") -> 3 4 - 4 | AN32: =IF(AL32<>"",ThirdPlaced!$I17,"") -> C
B33: =VLOOKUP(A31,Matches!$B$4:$K$113,8,0) -> Czech Rep. | C33: =VLOOKUP(A31,Matches!$B$4:$K$113,9,0) -> Mexico | E33: =VLOOKUP(D31,Matches!$B$4:$K$113,8,0) -> Switzerland | F33: =VLOOKUP(D31,Matches!$B$4:$K$113,9,0) -> Canada | H33: =VLOOKUP(G31,Matches!$B$4:$K$113,8,0) -> Scotland | I33: =VLOOKUP(G31,Matches!$B$4:$K$113,9,0) -> Brazil | K33: =VLOOKUP(J31,Matches!$B$4:$K$113,8,0) -> Turkey | L33: =VLOOKUP(J31,Matches!$B$4:$K$113,9,0) -> USA | N33: =VLOOKUP(M31,Matches!$B$4:$K$113,8,0) -> Curaçao | O33: =VLOOKUP(M31,Matches!$B$4:$K$113,9,0) -> Ivory Coast | Q33: =VLOOKUP(P31,Matches!$B$4:$K$113,8,0) -> Japan | R33: =VLOOKUP(P31,Matches!$B$4:$K$113,9,0) -> Sweden | T33: =VLOOKUP(S31,Matches!$B$4:$K$113,8,0) -> Egypt | U33: =VLOOKUP(S31,Matches!$B$4:$K$113,9,0) -> IR Iran | W33: =VLOOKUP(V31,Matches!$B$4:$K$113,8,0) -> Cape Verde | X33: =VLOOKUP(V31,Matches!$B$4:$K$113,9,0) -> Saudi Arabia | Z33: =VLOOKUP(Y31,Matches!$B$4:$K$113,8,0) -> Norway | AA33: =VLOOKUP(Y31,Matches!$B$4:$K$113,9,0) -> France | AC33: =VLOOKUP(AB31,Matches!$B$4:$K$113,8,0) -> Algeria | AD33: =VLOOKUP(AB31,Matches!$B$4:$K$113,9,0) -> Austria | AF33: =VLOOKUP(AE31,Matches!$B$4:$K$113,8,0) -> Colombia | AG33: =VLOOKUP(AE31,Matches!$B$4:$K$113,9,0) -> Portugal | AI33: =VLOOKUP(AH31,Matches!$B$4:$K$113,8,0) -> Panama | AJ33: =VLOOKUP(AH31,Matches!$B$4:$K$113,9,0) -> England | AL33: =IF(OR(ThirdPlaced!$D18>0,ThirdPlaced!$G18>0),ThirdPlaced!$C18,"") -> Saudi Arabia | AM33: =IF(AL33<>""," "&ThirdPlaced!$D18&" "&ThirdPlaced!$F18&Language!$E$197&ThirdPlaced!$G18,"") -> 3 6 - 7 | AN33: =IF(AL33<>"",ThirdPlaced!$I18,"") -> H
B34: 0 | C34: 1 | E34: 1 | F34: 0 | H34: 1 | I34: 3 | K34: 2 | L34: 2 | N34: 0 | O34: 0 | Q34: 3 | R34: 2 | T34: 2 | U34: 0 | W34: 1 | X34: 4 | Z34: 1 | AA34: 3 | AC34: 0 | AD34: 1 | AF34: 1 | AG34: 3 | AI34: 0 | AJ34: 4 | AL34: =IF(OR(ThirdPlaced!$D19>0,ThirdPlaced!$G19>0),ThirdPlaced!$C19,"") -> Senegal | AM34: =IF(AL34<>""," "&ThirdPlaced!$D19&" "&ThirdPlaced!$F19&Language!$E$197&ThirdPlaced!$G19,"") -> 3 5 - 6 | AN34: =IF(AL34<>"",ThirdPlaced!$I19,"") -> I
AL35: =IF(OR(ThirdPlaced!$D20>0,ThirdPlaced!$G20>0),ThirdPlaced!$C20,"") -> Sweden | AM35: =IF(AL35<>""," "&ThirdPlaced!$D20&" "&ThirdPlaced!$F20&Language!$E$197&ThirdPlaced!$G20,"") -> 3 3 - 5 | AN35: =IF(AL35<>"",ThirdPlaced!$I20,"") -> F
A36: 54 | B36: =VLOOKUP(A36,Matches!$B$4:$K$113,7,0) -> Monterrey | D36: 52 | E36: =VLOOKUP(D36,Matches!$B$4:$K$113,7,0) -> Seattle | G36: 50 | H36: =VLOOKUP(G36,Matches!$B$4:$K$113,7,0) -> Atlanta | J36: 60 | K36: =VLOOKUP(J36,Matches!$B$4:$K$113,7,0) -> San Francisco Bay Area | M36: 56 | N36: =VLOOKUP(M36,Matches!$B$4:$K$113,7,0) -> New York/New Jersey | P36: 58 | Q36: =VLOOKUP(P36,Matches!$B$4:$K$113,7,0) -> Kansas City | S36: 64 | T36: =VLOOKUP(S36,Matches!$B$4:$K$113,7,0) -> Vancouver | V36: 66 | W36: =VLOOKUP(V36,Matches!$B$4:$K$113,7,0) -> Guadalajara | Y36: 62 | Z36: =VLOOKUP(Y36,Matches!$B$4:$K$113,7,0) -> Toronto | AB36: 70 | AC36: =VLOOKUP(AB36,Matches!$B$4:$K$113,7,0) -> Dallas | AE36: 72 | AF36: =VLOOKUP(AE36,Matches!$B$4:$K$113,7,0) -> Atlanta | AH36: 68 | AI36: =VLOOKUP(AH36,Matches!$B$4:$K$113,7,0) -> Philadelphia | AL36: =IF(OR(ThirdPlaced!$D21>0,ThirdPlaced!$G21>0),ThirdPlaced!$C21,"") -> Qatar | AM36: =IF(AL36<>""," "&ThirdPlaced!$D21&" "&ThirdPlaced!$F21&Language!$E$197&ThirdPlaced!$G21,"") -> 3 3 - 5 | AN36: =IF(AL36<>"",ThirdPlaced!$I21,"") -> B
B37: =VLOOKUP(A36,Matches!$B$4:$K$113,5,0) -> 46198.125 | E37: =VLOOKUP(D36,Matches!$B$4:$K$113,5,0) -> 46197.875 | H37: =VLOOKUP(G36,Matches!$B$4:$K$113,5,0) -> 46198 | K37: =VLOOKUP(J36,Matches!$B$4:$K$113,5,0) -> 46199.167 | N37: =VLOOKUP(M36,Matches!$B$4:$K$113,5,0) -> 46198.917 | Q37: =VLOOKUP(P36,Matches!$B$4:$K$113,5,0) -> 46199.042 | T37: =VLOOKUP(S36,Matches!$B$4:$K$113,5,0) -> 46200.208 | W37: =VLOOKUP(V36,Matches!$B$4:$K$113,5,0) -> 46200.083 | Z37: =VLOOKUP(Y36,Matches!$B$4:$K$113,5,0) -> 46199.875 | AC37: =VLOOKUP(AB36,Matches!$B$4:$K$113,5,0) -> 46201.167 | AF37: =VLOOKUP(AE36,Matches!$B$4:$K$113,5,0) -> 46201.062 | AI37: =VLOOKUP(AH36,Matches!$B$4:$K$113,5,0) -> 46200.958 | AL37: =IF(OR(ThirdPlaced!$D22>0,ThirdPlaced!$G22>0),ThirdPlaced!$C22,"") -> Ghana | AM37: =IF(AL37<>""," "&ThirdPlaced!$D22&" "&ThirdPlaced!$F22&Language!$E$197&ThirdPlaced!$G22,"") -> 3 1 - 6 | AN37: =IF(AL37<>"",ThirdPlaced!$I22,"") -> L
B38: =VLOOKUP(A36,Matches!$B$4:$K$113,8,0) -> South Africa | C38: =VLOOKUP(A36,Matches!$B$4:$K$113,9,0) -> Rep. of Korea | E38: =VLOOKUP(D36,Matches!$B$4:$K$113,8,0) -> Bosnia/Herzeg. | F38: =VLOOKUP(D36,Matches!$B$4:$K$113,9,0) -> Qatar | H38: =VLOOKUP(G36,Matches!$B$4:$K$113,8,0) -> Morocco | I38: =VLOOKUP(G36,Matches!$B$4:$K$113,9,0) -> Haiti | K38: =VLOOKUP(J36,Matches!$B$4:$K$113,8,0) -> Paraguay | L38: =VLOOKUP(J36,Matches!$B$4:$K$113,9,0) -> Australia | N38: =VLOOKUP(M36,Matches!$B$4:$K$113,8,0) -> Ecuador | O38: =VLOOKUP(M36,Matches!$B$4:$K$113,9,0) -> Germany | Q38: =VLOOKUP(P36,Matches!$B$4:$K$113,8,0) -> Tunisia | R38: =VLOOKUP(P36,Matches!$B$4:$K$113,9,0) -> Netherlands | T38: =VLOOKUP(S36,Matches!$B$4:$K$113,8,0) -> New Zealand | U38: =VLOOKUP(S36,Matches!$B$4:$K$113,9,0) -> Belgium | W38: =VLOOKUP(V36,Matches!$B$4:$K$113,8,0) -> Uruguay | X38: =VLOOKUP(V36,Matches!$B$4:$K$113,9,0) -> Spain | Z38: =VLOOKUP(Y36,Matches!$B$4:$K$113,8,0) -> Senegal | AA38: =VLOOKUP(Y36,Matches!$B$4:$K$113,9,0) -> Iraq | AC38: =VLOOKUP(AB36,Matches!$B$4:$K$113,8,0) -> Jordan | AD38: =VLOOKUP(AB36,Matches!$B$4:$K$113,9,0) -> Argentina | AF38: =VLOOKUP(AE36,Matches!$B$4:$K$113,8,0) -> DR Congo | AG38: =VLOOKUP(AE36,Matches!$B$4:$K$113,9,0) -> Uzbekistan | AI38: =VLOOKUP(AH36,Matches!$B$4:$K$113,8,0) -> Croatia | AJ38: =VLOOKUP(AH36,Matches!$B$4:$K$113,9,0) -> Ghana | AL38: =IF(OR(ThirdPlaced!$D23>0,ThirdPlaced!$G23>0),ThirdPlaced!$C23,"") -> Australia | AM38: =IF(AL38<>""," "&ThirdPlaced!$D23&" "&ThirdPlaced!$F23&Language!$E$197&ThirdPlaced!$G23,"") -> 2 1 - 2 | AN38: =IF(AL38<>"",ThirdPlaced!$I23,"") -> D
B39: 0 | C39: 0 | E39: 1 | F39: 2 | H39: 3 | I39: 1 | K39: 0 | L39: 0 | N39: 1 | O39: 3 | Q39: 0 | R39: 3 | T39: 1 | U39: 3 | W39: 1 | X39: 3 | Z39: 2 | AA39: 0 | AC39: 0 | AD39: 4 | AF39: 2 | AG39: 2 | AI39: 2 | AJ39: 0 | AL39: =IF(OR(ThirdPlaced!$D24>0,ThirdPlaced!$G24>0),ThirdPlaced!$C24,"") -> Rep. of Korea | AM39: =IF(AL39<>""," "&ThirdPlaced!$D24&" "&ThirdPlaced!$F24&Language!$E$197&ThirdPlaced!$G24,"") -> 2 2 - 4 | AN39: =IF(AL39<>"",ThirdPlaced!$I24,"") -> A
AL40: =IF(OR(ThirdPlaced!$D25>0,ThirdPlaced!$G25>0),ThirdPlaced!$C25,"") -> New Zealand | AM40: =IF(AL40<>""," "&ThirdPlaced!$D25&" "&ThirdPlaced!$F25&Language!$E$197&ThirdPlaced!$G25,"") -> 1 2 - 6 | AN40: =IF(AL40<>"",ThirdPlaced!$I25,"") -> G
B41: =B9 -> Group A | E41: =E9 -> Group B | H41: =H9 -> Group C | K41: =K9 -> Group D | N41: =N9 -> Group E | Q41: =Q9 -> Group F | T41: =T9 -> Group G | W41: =W9 -> Group H | Z41: =Z9 -> Group I | AC41: =AC9 -> Group J | AF41: =AF9 -> Group K | AI41: =AI9 -> Group L | AL41: =IF(OR(ThirdPlaced!$D26>0,ThirdPlaced!$G26>0),ThirdPlaced!$C26,"") -> Uzbekistan | AM41: =IF(AL41<>""," "&ThirdPlaced!$D26&" "&ThirdPlaced!$F26&Language!$E$197&ThirdPlaced!$G26,"") -> 1 2 - 7 | AN41: =IF(AL41<>"",ThirdPlaced!$I26,"") -> K
A42: 1A | B42: =IF(CalcA!$L22,B3,"") -> Mexico | C42: =IF(CalcA!$L22,C3,"") -> 9 6 - 1 | D42: 1B | E42: =IF(CalcB!$L22,E3,"") -> Switzerland | F42: =IF(CalcB!$L22,F3,"") -> 9 6 - 1 | G42: 1C | H42: =IF(CalcC!$L22,H3,"") -> Brazil | I42: =IF(CalcC!$L22,I3,"") -> 9 9 - 1 | J42: 1D | K42: =IF(CalcD!$L22,K3,"") -> USA | L42: =IF(CalcD!$L22,L3,"") -> 7 5 - 2 | M42: 1E | N42: =IF(CalcE!$L22,N3,"") -> Germany | O42: =IF(CalcE!$L22,O3,"") -> 9 12 - 1 | P42: 1F | Q42: =IF(CalcF!$L22,Q3,"") -> Netherlands | R42: =IF(CalcF!$L22,R3,"") -> 9 7 - 1 | S42: 1G | T42: =IF(CalcG!$L22,T3,"") -> Belgium | U42: =IF(CalcG!$L22,U3,"") -> 9 9 - 3 | V42: 1H | W42: =IF(CalcH!$L22,W3,"") -> Spain | X42: =IF(CalcH!$L22,X3,"") -> 9 12 - 2 | Y42: 1I | Z42: =IF(CalcI!$L22,Z3,"") -> France | AA42: =IF(CalcI!$L22,AA3,"") -> 9 10 - 3 | AB42: 1J | AC42: =IF(CalcJ!$L22,AC3,"") -> Argentina | AD42: =IF(CalcJ!$L22,AD3,"") -> 9 11 - 1 | AE42: 1K | AF42: =IF(CalcK!$L22,AF3,"") -> Portugal | AG42: =IF(CalcK!$L22,AG3,"") -> 9 12 - 1 | AH42: 1L | AI42: =IF(CalcL!$L22,AI3,"") -> England | AJ42: =IF(CalcL!$L22,AJ3,"") -> 9 11 - 1 | AL42: =IF(OR(ThirdPlaced!$D27>0,ThirdPlaced!$G27>0),ThirdPlaced!$C27,"") -> Algeria | AM42: =IF(AL42<>""," "&ThirdPlaced!$D27&" "&ThirdPlaced!$F27&Language!$E$197&ThirdPlaced!$G27,"") -> 1 1 - 6 | AN42: =IF(AL42<>"",ThirdPlaced!$I27,"") -> J
A43: 2A | B43: =IF(CalcA!$L23,B4,"") -> Czech Rep. | C43: =IF(CalcA!$L23,C4,"") -> 4 2 - 2 | D43: 2B | E43: =IF(CalcB!$L23,E4,"") -> Canada | F43: =IF(CalcB!$L23,F4,"") -> 6 5 - 2 | G43: 2C | H43: =IF(CalcC!$L23,H4,"") -> Morocco | I43: =IF(CalcC!$L23,I4,"") -> 6 4 - 3 | J43: 2D | K43: =IF(CalcD!$L23,K4,"") -> Turkey | L43: =IF(CalcD!$L23,L4,"") -> 5 5 - 3 | M43: 2E | N43: =IF(CalcE!$L23,N4,"") -> Ecuador | O43: =IF(CalcE!$L23,O4,"") -> 6 6 - 4 | P43: 2F | Q43: =IF(CalcF!$L23,Q4,"") -> Japan | R43: =IF(CalcF!$L23,R4,"") -> 6 7 - 4 | S43: 2G | T43: =IF(CalcG!$L23,T4,"") -> Egypt | U43: =IF(CalcG!$L23,U4,"") -> 6 6 - 3 | V43: 2H | W43: =IF(CalcH!$L23,W4,"") -> Uruguay | X43: =IF(CalcH!$L23,X4,"") -> 6 6 - 4 | Y43: 2I | Z43: =IF(CalcI!$L23,Z4,"") -> Norway | AA43: =IF(CalcI!$L23,AA4,"") -> 6 5 - 4 | AB43: 2J | AC43: =IF(CalcJ!$L23,AC4,"") -> Austria | AD43: =IF(CalcJ!$L23,AD4,"") -> 6 3 - 3 | AE43: 2K | AF43: =IF(CalcK!$L23,AF4,"") -> Colombia | AG43: =IF(CalcK!$L23,AG4,"") -> 6 4 - 3 | AH43: 2L | AI43: =IF(CalcL!$L23,AI4,"") -> Croatia | AJ43: =IF(CalcL!$L23,AJ4,"") -> 6 6 - 3 | AL43: =IF(OR(ThirdPlaced!$D28>0,ThirdPlaced!$G28>0),ThirdPlaced!$C28,"") -> Ivory Coast | AM43: =IF(AL43<>""," "&ThirdPlaced!$D28&" "&ThirdPlaced!$F28&Language!$E$197&ThirdPlaced!$G28,"") -> 1 0 - 6 | AN43: =IF(AL43<>"",ThirdPlaced!$I28,"") -> E
...

Sheet DailySchedule
B1: =Language!$E$250 -> Daily schedule
M2: =Language!$E$261 -> Color favorites
B3: =Language!$E$260 -> Date | C3: =Language!$E$253 -> Time | D3: =Language!$E$254 -> Team 1 | E3: =Language!$E$255 -> Team 2 | F3: =Language!$E$251 -> Match No. | G3: =Language!$E$252 -> Teams | I3: =Language!$E$185 -> Venue | J3: =Language!$E$184 -> TV channel | M3: =Language!$E$262 -> Enter the group code here
B4: =INDEX(Matches!$B$4:$J$113,MATCH($F4,Matches!$B$4:$B$113,0),5) -> 46184.875 | C4: =INDEX(Matches!$B$4:$J$113,MATCH($F4,Matches!$B$4:$B$113,0),5) -> 46184.875 | D4: =INDEX(Matches!$B$4:$J$113,MATCH($F4,Matches!$B$4:$B$113,0),8) -> Mexico | E4: =INDEX(Matches!$B$4:$J$113,MATCH($F4,Matches!$B$4:$B$113,0),9) -> South Africa | F4: 1 | G4: =INDEX(Matches!$B$4:$J$113,MATCH($F4,Matches!$B$4:$B$113,0),2) -> A1 | H4: =INDEX(Matches!$B$4:$J$113,MATCH($F4,Matches!$B$4:$B$113,0),3) -> A2 | I4: =IFERROR(VLOOKUP($F4,Matches!$B$4:$H$113,7,0),"") -> Mexico City
B5: =INDEX(Matches!$B$4:$J$113,MATCH($F5,Matches!$B$4:$B$113,0),5) -> 46185.167 | C5: =INDEX(Matches!$B$4:$J$113,MATCH($F5,Matches!$B$4:$B$113,0),5) -> 46185.167 | D5: =INDEX(Matches!$B$4:$J$113,MATCH($F5,Matches!$B$4:$B$113,0),8) -> Rep. of Korea | E5: =INDEX(Matches!$B$4:$J$113,MATCH($F5,Matches!$B$4:$B$113,0),9) -> Czech Rep. | F5: 2 | G5: =INDEX(Matches!$B$4:$J$113,MATCH($F5,Matches!$B$4:$B$113,0),2) -> A3 | H5: =INDEX(Matches!$B$4:$J$113,MATCH($F5,Matches!$B$4:$B$113,0),3) -> A4 | I5: =IFERROR(VLOOKUP($F5,Matches!$B$4:$H$113,7,0),"") -> Guadalajara
M6: ¤
B7: =INDEX(Matches!$B$4:$J$113,MATCH($F7,Matches!$B$4:$B$113,0),5) -> 46185.875 | C7: =INDEX(Matches!$B$4:$J$113,MATCH($F7,Matches!$B$4:$B$113,0),5) -> 46185.875 | D7: =INDEX(Matches!$B$4:$J$113,MATCH($F7,Matches!$B$4:$B$113,0),8) -> Canada | E7: =INDEX(Matches!$B$4:$J$113,MATCH($F7,Matches!$B$4:$B$113,0),9) -> Bosnia/Herzeg. | F7: 3 | G7: =INDEX(Matches!$B$4:$J$113,MATCH($F7,Matches!$B$4:$B$113,0),2) -> B1 | H7: =INDEX(Matches!$B$4:$J$113,MATCH($F7,Matches!$B$4:$B$113,0),3) -> B2 | I7: =IFERROR(VLOOKUP($F7,Matches!$B$4:$H$113,7,0),"") -> Toronto | M7: L1 | N7: =IFERROR(VLOOKUP(M7,Groups!$B$7:$D$65,3,0),"") -> England
B8: =INDEX(Matches!$B$4:$J$113,MATCH($F8,Matches!$B$4:$B$113,0),5) -> 46186.125 | C8: =INDEX(Matches!$B$4:$J$113,MATCH($F8,Matches!$B$4:$B$113,0),5) -> 46186.125 | D8: =INDEX(Matches!$B$4:$J$113,MATCH($F8,Matches!$B$4:$B$113,0),8) -> USA | E8: =INDEX(Matches!$B$4:$J$113,MATCH($F8,Matches!$B$4:$B$113,0),9) -> Paraguay | F8: 4 | G8: =INDEX(Matches!$B$4:$J$113,MATCH($F8,Matches!$B$4:$B$113,0),2) -> D1 | H8: =INDEX(Matches!$B$4:$J$113,MATCH($F8,Matches!$B$4:$B$113,0),3) -> D2 | I8: =IFERROR(VLOOKUP($F8,Matches!$B$4:$H$113,7,0),"") -> Los Angeles | M8: D1 | N8: =IFERROR(VLOOKUP(M8,Groups!$B$7:$D$65,3,0),"") -> USA
M9: B1 | N9: =IFERROR(VLOOKUP(M9,Groups!$B$7:$D$65,3,0),"") -> Canada
B10: =INDEX(Matches!$B$4:$J$113,MATCH($F10,Matches!$B$4:$B$113,0),5) -> 46186.875 | C10: =INDEX(Matches!$B$4:$J$113,MATCH($F10,Matches!$B$4:$B$113,0),5) -> 46186.875 | D10: =INDEX(Matches!$B$4:$J$113,MATCH($F10,Matches!$B$4:$B$113,0),8) -> Qatar | E10: =INDEX(Matches!$B$4:$J$113,MATCH($F10,Matches!$B$4:$B$113,0),9) -> Switzerland | F10: 8 | G10: =INDEX(Matches!$B$4:$J$113,MATCH($F10,Matches!$B$4:$B$113,0),2) -> B3 | H10: =INDEX(Matches!$B$4:$J$113,MATCH($F10,Matches!$B$4:$B$113,0),3) -> B4 | I10: =IFERROR(VLOOKUP($F10,Matches!$B$4:$H$113,7,0),"") -> San Francisco Bay Area | M10: A1 | N10: =IFERROR(VLOOKUP(M10,Groups!$B$7:$D$65,3,0),"") -> Mexico
B11: =INDEX(Matches!$B$4:$J$113,MATCH($F11,Matches!$B$4:$B$113,0),5) -> 46187 | C11: =INDEX(Matches!$B$4:$J$113,MATCH($F11,Matches!$B$4:$B$113,0),5) -> 46187 | D11: =INDEX(Matches!$B$4:$J$113,MATCH($F11,Matches!$B$4:$B$113,0),8) -> Brazil | E11: =INDEX(Matches!$B$4:$J$113,MATCH($F11,Matches!$B$4:$B$113,0),9) -> Morocco | F11: 7 | G11: =INDEX(Matches!$B$4:$J$113,MATCH($F11,Matches!$B$4:$B$113,0),2) -> C1 | H11: =INDEX(Matches!$B$4:$J$113,MATCH($F11,Matches!$B$4:$B$113,0),3) -> C2 | I11: =IFERROR(VLOOKUP($F11,Matches!$B$4:$H$113,7,0),"") -> New York/New Jersey
B12: =INDEX(Matches!$B$4:$J$113,MATCH($F12,Matches!$B$4:$B$113,0),5) -> 46187.125 | C12: =INDEX(Matches!$B$4:$J$113,MATCH($F12,Matches!$B$4:$B$113,0),5) -> 46187.125 | D12: =INDEX(Matches!$B$4:$J$113,MATCH($F12,Matches!$B$4:$B$113,0),8) -> Haiti | E12: =INDEX(Matches!$B$4:$J$113,MATCH($F12,Matches!$B$4:$B$113,0),9) -> Scotland | F12: 5 | G12: =INDEX(Matches!$B$4:$J$113,MATCH($F12,Matches!$B$4:$B$113,0),2) -> C3 | H12: =INDEX(Matches!$B$4:$J$113,MATCH($F12,Matches!$B$4:$B$113,0),3) -> C4 | I12: =IFERROR(VLOOKUP($F12,Matches!$B$4:$H$113,7,0),"") -> Boston
B13: =INDEX(Matches!$B$4:$J$113,MATCH($F13,Matches!$B$4:$B$113,0),5) -> 46187.25 | C13: =INDEX(Matches!$B$4:$J$113,MATCH($F13,Matches!$B$4:$B$113,0),5) -> 46187.25 | D13: =INDEX(Matches!$B$4:$J$113,MATCH($F13,Matches!$B$4:$B$113,0),8) -> Australia | E13: =INDEX(Matches!$B$4:$J$113,MATCH($F13,Matches!$B$4:$B$113,0),9) -> Turkey | F13: 6 | G13: =INDEX(Matches!$B$4:$J$113,MATCH($F13,Matches!$B$4:$B$113,0),2) -> D3 | H13: =INDEX(Matches!$B$4:$J$113,MATCH($F13,Matches!$B$4:$B$113,0),3) -> D4 | I13: =IFERROR(VLOOKUP($F13,Matches!$B$4:$H$113,7,0),"") -> Vancouver
B15: =INDEX(Matches!$B$4:$J$113,MATCH($F15,Matches!$B$4:$B$113,0),5) -> 46187.792 | C15: =INDEX(Matches!$B$4:$J$113,MATCH($F15,Matches!$B$4:$B$113,0),5) -> 46187.792 | D15: =INDEX(Matches!$B$4:$J$113,MATCH($F15,Matches!$B$4:$B$113,0),8) -> Germany | E15: =INDEX(Matches!$B$4:$J$113,MATCH($F15,Matches!$B$4:$B$113,0),9) -> Curaçao | F15: 10 | G15: =INDEX(Matches!$B$4:$J$113,MATCH($F15,Matches!$B$4:$B$113,0),2) -> E1 | H15: =INDEX(Matches!$B$4:$J$113,MATCH($F15,Matches!$B$4:$B$113,0),3) -> E2 | I15: =IFERROR(VLOOKUP($F15,Matches!$B$4:$H$113,7,0),"") -> Houston
B16: =INDEX(Matches!$B$4:$J$113,MATCH($F16,Matches!$B$4:$B$113,0),5) -> 46187.917 | C16: =INDEX(Matches!$B$4:$J$113,MATCH($F16,Matches!$B$4:$B$113,0),5) -> 46187.917 | D16: =INDEX(Matches!$B$4:$J$113,MATCH($F16,Matches!$B$4:$B$113,0),8) -> Netherlands | E16: =INDEX(Matches!$B$4:$J$113,MATCH($F16,Matches!$B$4:$B$113,0),9) -> Japan | F16: 11 | G16: =INDEX(Matches!$B$4:$J$113,MATCH($F16,Matches!$B$4:$B$113,0),2) -> F1 | H16: =INDEX(Matches!$B$4:$J$113,MATCH($F16,Matches!$B$4:$B$113,0),3) -> F2 | I16: =IFERROR(VLOOKUP($F16,Matches!$B$4:$H$113,7,0),"") -> Dallas
B17: =INDEX(Matches!$B$4:$J$113,MATCH($F17,Matches!$B$4:$B$113,0),5) -> 46188.042 | C17: =INDEX(Matches!$B$4:$J$113,MATCH($F17,Matches!$B$4:$B$113,0),5) -> 46188.042 | D17: =INDEX(Matches!$B$4:$J$113,MATCH($F17,Matches!$B$4:$B$113,0),8) -> Ivory Coast | E17: =INDEX(Matches!$B$4:$J$113,MATCH($F17,Matches!$B$4:$B$113,0),9) -> Ecuador | F17: 9 | G17: =INDEX(Matches!$B$4:$J$113,MATCH($F17,Matches!$B$4:$B$113,0),2) -> E3 | H17: =INDEX(Matches!$B$4:$J$113,MATCH($F17,Matches!$B$4:$B$113,0),3) -> E4 | I17: =IFERROR(VLOOKUP($F17,Matches!$B$4:$H$113,7,0),"") -> Philadelphia
B18: =INDEX(Matches!$B$4:$J$113,MATCH($F18,Matches!$B$4:$B$113,0),5) -> 46188.167 | C18: =INDEX(Matches!$B$4:$J$113,MATCH($F18,Matches!$B$4:$B$113,0),5) -> 46188.167 | D18: =INDEX(Matches!$B$4:$J$113,MATCH($F18,Matches!$B$4:$B$113,0),8) -> Sweden | E18: =INDEX(Matches!$B$4:$J$113,MATCH($F18,Matches!$B$4:$B$113,0),9) -> Tunisia | F18: 12 | G18: =INDEX(Matches!$B$4:$J$113,MATCH($F18,Matches!$B$4:$B$113,0),2) -> F3 | H18: =INDEX(Matches!$B$4:$J$113,MATCH($F18,Matches!$B$4:$B$113,0),3) -> F4 | I18: =IFERROR(VLOOKUP($F18,Matches!$B$4:$H$113,7,0),"") -> Monterrey
B20: =INDEX(Matches!$B$4:$J$113,MATCH($F20,Matches!$B$4:$B$113,0),5) -> 46188.75 | C20: =INDEX(Matches!$B$4:$J$113,MATCH($F20,Matches!$B$4:$B$113,0),5) -> 46188.75 | D20: =INDEX(Matches!$B$4:$J$113,MATCH($F20,Matches!$B$4:$B$113,0),8) -> Spain | E20: =INDEX(Matches!$B$4:$J$113,MATCH($F20,Matches!$B$4:$B$113,0),9) -> Cape Verde | F20: 14 | G20: =INDEX(Matches!$B$4:$J$113,MATCH($F20,Matches!$B$4:$B$113,0),2) -> H1 | H20: =INDEX(Matches!$B$4:$J$113,MATCH($F20,Matches!$B$4:$B$113,0),3) -> H2 | I20: =IFERROR(VLOOKUP($F20,Matches!$B$4:$H$113,7,0),"") -> Atlanta
B21: =INDEX(Matches!$B$4:$J$113,MATCH($F21,Matches!$B$4:$B$113,0),5) -> 46188.875 | C21: =INDEX(Matches!$B$4:$J$113,MATCH($F21,Matches!$B$4:$B$113,0),5) -> 46188.875 | D21: =INDEX(Matches!$B$4:$J$113,MATCH($F21,Matches!$B$4:$B$113,0),8) -> Belgium | E21: =INDEX(Matches!$B$4:$J$113,MATCH($F21,Matches!$B$4:$B$113,0),9) -> Egypt | F21: 16 | G21: =INDEX(Matches!$B$4:$J$113,MATCH($F21,Matches!$B$4:$B$113,0),2) -> G1 | H21: =INDEX(Matches!$B$4:$J$113,MATCH($F21,Matches!$B$4:$B$113,0),3) -> G2 | I21: =IFERROR(VLOOKUP($F21,Matches!$B$4:$H$113,7,0),"") -> Seattle
B22: =INDEX(Matches!$B$4:$J$113,MATCH($F22,Matches!$B$4:$B$113,0),5) -> 46189 | C22: =INDEX(Matches!$B$4:$J$113,MATCH($F22,Matches!$B$4:$B$113,0),5) -> 46189 | D22: =INDEX(Matches!$B$4:$J$113,MATCH($F22,Matches!$B$4:$B$113,0),8) -> Saudi Arabia | E22: =INDEX(Matches!$B$4:$J$113,MATCH($F22,Matches!$B$4:$B$113,0),9) -> Uruguay | F22: 13 | G22: =INDEX(Matches!$B$4:$J$113,MATCH($F22,Matches!$B$4:$B$113,0),2) -> H3 | H22: =INDEX(Matches!$B$4:$J$113,MATCH($F22,Matches!$B$4:$B$113,0),3) -> H4 | I22: =IFERROR(VLOOKUP($F22,Matches!$B$4:$H$113,7,0),"") -> Miami
B23: =INDEX(Matches!$B$4:$J$113,MATCH($F23,Matches!$B$4:$B$113,0),5) -> 46189.125 | C23: =INDEX(Matches!$B$4:$J$113,MATCH($F23,Matches!$B$4:$B$113,0),5) -> 46189.125 | D23: =INDEX(Matches!$B$4:$J$113,MATCH($F23,Matches!$B$4:$B$113,0),8) -> IR Iran | E23: =INDEX(Matches!$B$4:$J$113,MATCH($F23,Matches!$B$4:$B$113,0),9) -> New Zealand | F23: 15 | G23: =INDEX(Matches!$B$4:$J$113,MATCH($F23,Matches!$B$4:$B$113,0),2) -> G3 | H23: =INDEX(Matches!$B$4:$J$113,MATCH($F23,Matches!$B$4:$B$113,0),3) -> G4 | I23: =IFERROR(VLOOKUP($F23,Matches!$B$4:$H$113,7,0),"") -> Los Angeles
B25: =INDEX(Matches!$B$4:$J$113,MATCH($F25,Matches!$B$4:$B$113,0),5) -> 46189.875 | C25: =INDEX(Matches!$B$4:$J$113,MATCH($F25,Matches!$B$4:$B$113,0),5) -> 46189.875 | D25: =INDEX(Matches!$B$4:$J$113,MATCH($F25,Matches!$B$4:$B$113,0),8) -> France | E25: =INDEX(Matches!$B$4:$J$113,MATCH($F25,Matches!$B$4:$B$113,0),9) -> Senegal | F25: 17 | G25: =INDEX(Matches!$B$4:$J$113,MATCH($F25,Matches!$B$4:$B$113,0),2) -> I1 | H25: =INDEX(Matches!$B$4:$J$113,MATCH($F25,Matches!$B$4:$B$113,0),3) -> I2 | I25: =IFERROR(VLOOKUP($F25,Matches!$B$4:$H$113,7,0),"") -> New York/New Jersey
... B91: =INDEX(Matches!$B$4:$J$113,MATCH($F91,Matches!$B$4:$B$113,0),5) -> 46201.167 | C91: =INDEX(Matches!$B$4:$J$113,MATCH($F91,Matches!$B$4:$B$113,0),5) -> 46201.167 | D91: =INDEX(Matches!$B$4:$J$113,MATCH($F91,Matches!$B$4:$B$113,0),8) -> Jordan | E91: =INDEX(Matches!$B$4:$J$113,MATCH($F91,Matches!$B$4:$B$113,0),9) -> Argentina | F91: 70 | G91: =INDEX(Matches!$B$4:$J$113,MATCH($F91,Matches!$B$4:$B$113,0),2) -> J4 | H91: =INDEX(Matches!$B$4:$J$113,MATCH($F91,Matches!$B$4:$B$113,0),3) -> J1 | I91: =IFERROR(VLOOKUP($F91,Matches!$B$4:$H$113,7,0),"") -> Dallas
B93: =Language!$E$256 -> Round of 32
B94: =INDEX(Matches!$B$4:$J$113,MATCH($F94,Matches!$B$4:$B$113,0),5) -> 46201.875 | C94: =INDEX(Matches!$B$4:$J$113,MATCH($F94,Matches!$B$4:$B$113,0),5) -> 46201.875 | D94: =INDEX(Matches!$B$4:$J$113,MATCH($F94,Matches!$B$4:$B$113,0),8) -> Czech Rep. | E94: =INDEX(Matches!$B$4:$J$113,MATCH($F94,Matches!$B$4:$B$113,0),9) -> Canada | F94: 73 | G94: =INDEX(Matches!$B$4:$J$113,MATCH($F94,Matches!$B$4:$B$113,0),2) -> 2A | H94: =INDEX(Matches!$B$4:$J$113,MATCH($F94,Matches!$B$4:$B$113,0),3) -> 2B | I94: =IFERROR(VLOOKUP($F94,Matches!$B$4:$H$113,7,0),"") -> Los Angeles
B96: =INDEX(Matches!$B$4:$J$113,MATCH($F96,Matches!$B$4:$B$113,0),5) -> 46202.792 | C96: =INDEX(Matches!$B$4:$J$113,MATCH($F96,Matches!$B$4:$B$113,0),5) -> 46202.792 | D96: =INDEX(Matches!$B$4:$J$113,MATCH($F96,Matches!$B$4:$B$113,0),8) -> Brazil | E96: =INDEX(Matches!$B$4:$J$113,MATCH($F96,Matches!$B$4:$B$113,0),9) -> Japan | F96: 76 | G96: =INDEX(Matches!$B$4:$J$113,MATCH($F96,Matches!$B$4:$B$113,0),2) -> 1C | H96: =INDEX(Matches!$B$4:$J$113,MATCH($F96,Matches!$B$4:$B$113,0),3) -> 2F | I96: =IFERROR(VLOOKUP($F96,Matches!$B$4:$H$113,7,0),"") -> Houston
B97: =INDEX(Matches!$B$4:$J$113,MATCH($F97,Matches!$B$4:$B$113,0),5) -> 46202.938 | C97: =INDEX(Matches!$B$4:$J$113,MATCH($F97,Matches!$B$4:$B$113,0),5) -> 46202.938 | D97: =INDEX(Matches!$B$4:$J$113,MATCH($F97,Matches!$B$4:$B$113,0),8) -> Germany | E97: =INDEX(Matches!$B$4:$J$113,MATCH($F97,Matches!$B$4:$B$113,0),9) -> Scotland | F97: 74 | G97: =INDEX(Matches!$B$4:$J$113,MATCH($F97,Matches!$B$4:$B$113,0),2) -> 1E | H97: =INDEX(Matches!$B$4:$J$113,MATCH($F97,Matches!$B$4:$B$113,0),3) -> 3-ABCDF | I97: =IFERROR(VLOOKUP($F97,Matches!$B$4:$H$113,7,0),"") -> Boston
B98: =INDEX(Matches!$B$4:$J$113,MATCH($F98,Matches!$B$4:$B$113,0),5) -> 46203.125 | C98: =INDEX(Matches!$B$4:$J$113,MATCH($F98,Matches!$B$4:$B$113,0),5) -> 46203.125 | D98: =INDEX(Matches!$B$4:$J$113,MATCH($F98,Matches!$B$4:$B$113,0),8) -> Netherlands | E98: =INDEX(Matches!$B$4:$J$113,MATCH($F98,Matches!$B$4:$B$113,0),9) -> Morocco | F98: 75 | G98: =INDEX(Matches!$B$4:$J$113,MATCH($F98,Matches!$B$4:$B$113,0),2) -> 1F | H98: =INDEX(Matches!$B$4:$J$113,MATCH($F98,Matches!$B$4:$B$113,0),3) -> 2C | I98: =IFERROR(VLOOKUP($F98,Matches!$B$4:$H$113,7,0),"") -> Monterrey
B100: =INDEX(Matches!$B$4:$J$113,MATCH($F100,Matches!$B$4:$B$113,0),5) -> 46203.792 | C100: =INDEX(Matches!$B$4:$J$113,MATCH($F100,Matches!$B$4:$B$113,0),5) -> 46203.792 | D100: =INDEX(Matches!$B$4:$J$113,MATCH($F100,Matches!$B$4:$B$113,0),8) -> Ecuador | E100: =INDEX(Matches!$B$4:$J$113,MATCH($F100,Matches!$B$4:$B$113,0),9) -> Norway | F100: 78 | G100: =INDEX(Matches!$B$4:$J$113,MATCH($F100,Matches!$B$4:$B$113,0),2) -> 2E | H100: =INDEX(Matches!$B$4:$J$113,MATCH($F100,Matches!$B$4:$B$113,0),3) -> 2I | I100: =IFERROR(VLOOKUP($F100,Matches!$B$4:$H$113,7,0),"") -> Dallas
B101: =INDEX(Matches!$B$4:$J$113,MATCH($F101,Matches!$B$4:$B$113,0),5) -> 46203.958 | C101: =INDEX(Matches!$B$4:$J$113,MATCH($F101,Matches!$B$4:$B$113,0),5) -> 46203.958 | D101: =INDEX(Matches!$B$4:$J$113,MATCH($F101,Matches!$B$4:$B$113,0),8) -> France | E101: =INDEX(Matches!$B$4:$J$113,MATCH($F101,Matches!$B$4:$B$113,0),9) -> Australia | F101: 77 | G101: =INDEX(Matches!$B$4:$J$113,MATCH($F101,Matches!$B$4:$B$113,0),2) -> 1I | H101: =INDEX(Matches!$B$4:$J$113,MATCH($F101,Matches!$B$4:$B$113,0),3) -> 3-CDFGH | I101: =IFERROR(VLOOKUP($F101,Matches!$B$4:$H$113,7,0),"") -> New York/New Jersey
B102: =INDEX(Matches!$B$4:$J$113,MATCH($F102,Matches!$B$4:$B$113,0),5) -> 46204.125 | C102: =INDEX(Matches!$B$4:$J$113,MATCH($F102,Matches!$B$4:$B$113,0),5) -> 46204.125 | D102: =INDEX(Matches!$B$4:$J$113,MATCH($F102,Matches!$B$4:$B$113,0),8) -> Mexico | E102: =INDEX(Matches!$B$4:$J$113,MATCH($F102,Matches!$B$4:$B$113,0),9) -> Saudi Arabia | F102: 79 | G102: =INDEX(Matches!$B$4:$J$113,MATCH($F102,Matches!$B$4:$B$113,0),2) -> 1A | H102: =INDEX(Matches!$B$4:$J$113,MATCH($F102,Matches!$B$4:$B$113,0),3) -> 3-CEFHI | I102: =IFERROR(VLOOKUP($F102,Matches!$B$4:$H$113,7,0),"") -> Mexico City
B104: =INDEX(Matches!$B$4:$J$113,MATCH($F104,Matches!$B$4:$B$113,0),5) -> 46204.75 | C104: =INDEX(Matches!$B$4:$J$113,MATCH($F104,Matches!$B$4:$B$113,0),5) -> 46204.75 | D104: =INDEX(Matches!$B$4:$J$113,MATCH($F104,Matches!$B$4:$B$113,0),8) -> England | E104: =INDEX(Matches!$B$4:$J$113,MATCH($F104,Matches!$B$4:$B$113,0),9) -> Senegal | F104: 80 | G104: =INDEX(Matches!$B$4:$J$113,MATCH($F104,Matches!$B$4:$B$113,0),2) -> 1L | H104: =INDEX(Matches!$B$4:$J$113,MATCH($F104,Matches!$B$4:$B$113,0),3) -> 3-EHIJK | I104: =IFERROR(VLOOKUP($F104,Matches!$B$4:$H$113,7,0),"") -> Atlanta
B105: =INDEX(Matches!$B$4:$J$113,MATCH($F105,Matches!$B$4:$B$113,0),5) -> 46204.917 | C105: =INDEX(Matches!$B$4:$J$113,MATCH($F105,Matches!$B$4:$B$113,0),5) -> 46204.917 | D105: =INDEX(Matches!$B$4:$J$113,MATCH($F105,Matches!$B$4:$B$113,0),8) -> Belgium | E105: =INDEX(Matches!$B$4:$J$113,MATCH($F105,Matches!$B$4:$B$113,0),9) -> Rep. of Korea | F105: 82 | G105: =INDEX(Matches!$B$4:$J$113,MATCH($F105,Matches!$B$4:$B$113,0),2) -> 1G | H105: =INDEX(Matches!$B$4:$J$113,MATCH($F105,Matches!$B$4:$B$113,0),3) -> 3-AEHIJ | I105: =IFERROR(VLOOKUP($F105,Matches!$B$4:$H$113,7,0),"") -> Seattle
B106: =INDEX(Matches!$B$4:$J$113,MATCH($F106,Matches!$B$4:$B$113,0),5) -> 46205.083 | C106: =INDEX(Matches!$B$4:$J$113,MATCH($F106,Matches!$B$4:$B$113,0),5) -> 46205.083 | D106: =INDEX(Matches!$B$4:$J$113,MATCH($F106,Matches!$B$4:$B$113,0),8) -> USA | E106: =INDEX(Matches!$B$4:$J$113,MATCH($F106,Matches!$B$4:$B$113,0),9) -> Qatar | F106: 81 | G106: =INDEX(Matches!$B$4:$J$113,MATCH($F106,Matches!$B$4:$B$113,0),2) -> 1D | H106: =INDEX(Matches!$B$4:$J$113,MATCH($F106,Matches!$B$4:$B$113,0),3) -> 3-BEFIJ | I106: =IFERROR(VLOOKUP($F106,Matches!$B$4:$H$113,7,0),"") -> San Francisco Bay Area
B108: =INDEX(Matches!$B$4:$J$113,MATCH($F108,Matches!$B$4:$B$113,0),5) -> 46205.875 | C108: =INDEX(Matches!$B$4:$J$113,MATCH($F108,Matches!$B$4:$B$113,0),5) -> 46205.875 | D108: =INDEX(Matches!$B$4:$J$113,MATCH($F108,Matches!$B$4:$B$113,0),8) -> Spain | E108: =INDEX(Matches!$B$4:$J$113,MATCH($F108,Matches!$B$4:$B$113,0),9) -> Austria | F108: 84 | G108: =INDEX(Matches!$B$4:$J$113,MATCH($F108,Matches!$B$4:$B$113,0),2) -> 1H | H108: =INDEX(Matches!$B$4:$J$113,MATCH($F108,Matches!$B$4:$B$113,0),3) -> 2J | I108: =IFERROR(VLOOKUP($F108,Matches!$B$4:$H$113,7,0),"") -> Los Angeles
B109: =INDEX(Matches!$B$4:$J$113,MATCH($F109,Matches!$B$4:$B$113,0),5) -> 46206.042 | C109: =INDEX(Matches!$B$4:$J$113,MATCH($F109,Matches!$B$4:$B$113,0),5) -> 46206.042 | D109: =INDEX(Matches!$B$4:$J$113,MATCH($F109,Matches!$B$4:$B$113,0),8) -> Colombia | E109: =INDEX(Matches!$B$4:$J$113,MATCH($F109,Matches!$B$4:$B$113,0),9) -> Croatia | F109: 83 | G109: =INDEX(Matches!$B$4:$J$113,MATCH($F109,Matches!$B$4:$B$113,0),2) -> 2K | H109: =INDEX(Matches!$B$4:$J$113,MATCH($F109,Matches!$B$4:$B$113,0),3) -> 2L | I109: =IFERROR(VLOOKUP($F109,Matches!$B$4:$H$113,7,0),"") -> Toronto
... B114: =INDEX(Matches!$B$4:$J$113,MATCH($F114,Matches!$B$4:$B$113,0),5) -> 46207.146 | C114: =INDEX(Matches!$B$4:$J$113,MATCH($F114,Matches!$B$4:$B$113,0),5) -> 46207.146 | D114: =INDEX(Matches!$B$4:$J$113,MATCH($F114,Matches!$B$4:$B$113,0),8) -> Portugal | E114: =INDEX(Matches!$B$4:$J$113,MATCH($F114,Matches!$B$4:$B$113,0),9) -> Ghana | F114: 87 | G114: =INDEX(Matches!$B$4:$J$113,MATCH($F114,Matches!$B$4:$B$113,0),2) -> 1K | H114: =INDEX(Matches!$B$4:$J$113,MATCH($F114,Matches!$B$4:$B$113,0),3) -> 3-DEIJL | I114: =IFERROR(VLOOKUP($F114,Matches!$B$4:$H$113,7,0),"") -> Kansas City
B116: =Language!$E$257 -> Round of 16
B117: =INDEX(Matches!$B$4:$J$113,MATCH($F117,Matches!$B$4:$B$113,0),5) -> 46207.792 | C117: =INDEX(Matches!$B$4:$J$113,MATCH($F117,Matches!$B$4:$B$113,0),5) -> 46207.792 | D117: ='World Cup'!$E$60 -> Czech Rep. | E117: ='World Cup'!$F$60 -> Netherlands | F117: 90 | G117: =INDEX(Matches!$B$4:$J$113,MATCH($F117,Matches!$B$4:$B$113,0),2) -> W73 | H117: =INDEX(Matches!$B$4:$J$113,MATCH($F117,Matches!$B$4:$B$113,0),3) -> W75 | I117: =IFERROR(VLOOKUP($F117,Matches!$B$4:$H$113,7,0),"") -> Houston
B118: =INDEX(Matches!$B$4:$J$113,MATCH($F118,Matches!$B$4:$B$113,0),5) -> 46207.958 | C118: =INDEX(Matches!$B$4:$J$113,MATCH($F118,Matches!$B$4:$B$113,0),5) -> 46207.958 | D118: ='World Cup'!$B$60 -> Germany | E118: ='World Cup'!$C$60 -> France | F118: 89 | G118: =INDEX(Matches!$B$4:$J$113,MATCH($F118,Matches!$B$4:$B$113,0),2) -> W74 | H118: =INDEX(Matches!$B$4:$J$113,MATCH($F118,Matches!$B$4:$B$113,0),3) -> W77 | I118: =IFERROR(VLOOKUP($F118,Matches!$B$4:$H$113,7,0),"") -> Philadelphia
...

Sheet FairPlay
B2: =Language!$E$123 -> Fair play
B3: =Language!$E$193 -> Here, the penalty points for the fair play rating can be entered.
A5: A | B5: =Language!$E$130&" "&A5 -> Group A | C5: =Language!$E$174 -> Rating | D5: E | E5: =Language!$E$130&" "&D5 -> Group E | F5: =Language!$E$174 -> Rating | G5: I | H5: =Language!$E$130&" "&G5 -> Group I | I5: =Language!$E$174 -> Rating
B6: =VLOOKUP(A5&"1",Groups!$B$7:$D$65,3,0) -> Mexico | C6: 0 | E6: =VLOOKUP(D5&"1",Groups!$B$7:$D$65,3,0) -> Germany | F6: 0 | H6: =VLOOKUP(G5&"1",Groups!$B$7:$D$65,3,0) -> France | I6: 0
B7: =VLOOKUP(A5&"2",Groups!$B$7:$D$65,3,0) -> South Africa | C7: 0 | E7: =VLOOKUP(D5&"2",Groups!$B$7:$D$65,3,0) -> Curaçao | F7: 0 | H7: =VLOOKUP(G5&"2",Groups!$B$7:$D$65,3,0) -> Senegal | I7: 0
B8: =VLOOKUP(A5&"3",Groups!$B$7:$D$65,3,0) -> Rep. of Korea | C8: 0 | E8: =VLOOKUP(D5&"3",Groups!$B$7:$D$65,3,0) -> Ivory Coast | F8: 0 | H8: =VLOOKUP(G5&"3",Groups!$B$7:$D$65,3,0) -> Iraq | I8: 0
B9: =VLOOKUP(A5&"4",Groups!$B$7:$D$65,3,0) -> Czech Rep. | C9: 0 | E9: =VLOOKUP(D5&"4",Groups!$B$7:$D$65,3,0) -> Ecuador | F9: 0 | H9: =VLOOKUP(G5&"4",Groups!$B$7:$D$65,3,0) -> Norway | I9: 0
A11: B | B11: =Language!$E$130&" "&A11 -> Group B | C11: =Language!$E$174 -> Rating | D11: F | E11: =Language!$E$130&" "&D11 -> Group F | F11: =Language!$E$174 -> Rating | G11: J | H11: =Language!$E$130&" "&G11 -> Group J | I11: =Language!$E$174 -> Rating
B12: =VLOOKUP(A11&"1",Groups!$B$7:$D$65,3,0) -> Canada | C12: 0 | E12: =VLOOKUP(D11&"1",Groups!$B$7:$D$65,3,0) -> Netherlands | F12: 0 | H12: =VLOOKUP(G11&"1",Groups!$B$7:$D$65,3,0) -> Argentina | I12: 0
B13: =VLOOKUP(A11&"2",Groups!$B$7:$D$65,3,0) -> Bosnia/Herzeg. | C13: 0 | E13: =VLOOKUP(D11&"2",Groups!$B$7:$D$65,3,0) -> Japan | F13: 0 | H13: =VLOOKUP(G11&"2",Groups!$B$7:$D$65,3,0) -> Algeria | I13: 0
B14: =VLOOKUP(A11&"3",Groups!$B$7:$D$65,3,0) -> Qatar | C14: 0 | E14: =VLOOKUP(D11&"3",Groups!$B$7:$D$65,3,0) -> Sweden | F14: 0 | H14: =VLOOKUP(G11&"3",Groups!$B$7:$D$65,3,0) -> Austria | I14: 0
B15: =VLOOKUP(A11&"4",Groups!$B$7:$D$65,3,0) -> Switzerland | C15: 0 | E15: =VLOOKUP(D11&"4",Groups!$B$7:$D$65,3,0) -> Tunisia | F15: 0 | H15: =VLOOKUP(G11&"4",Groups!$B$7:$D$65,3,0) -> Jordan | I15: 0
A17: C | B17: =Language!$E$130&" "&A17 -> Group C | C17: =Language!$E$174 -> Rating | D17: G | E17: =Language!$E$130&" "&D17 -> Group G | F17: =Language!$E$174 -> Rating | G17: K | H17: =Language!$E$130&" "&G17 -> Group K | I17: =Language!$E$174 -> Rating
B18: =VLOOKUP(A17&"1",Groups!$B$7:$D$65,3,0) -> Brazil | C18: 0 | E18: =VLOOKUP(D17&"1",Groups!$B$7:$D$65,3,0) -> Belgium | F18: 0 | H18: =VLOOKUP(G17&"1",Groups!$B$7:$D$65,3,0) -> Portugal | I18: 0
B19: =VLOOKUP(A17&"2",Groups!$B$7:$D$65,3,0) -> Morocco | C19: 0 | E19: =VLOOKUP(D17&"2",Groups!$B$7:$D$65,3,0) -> Egypt | F19: 0 | H19: =VLOOKUP(G17&"2",Groups!$B$7:$D$65,3,0) -> DR Congo | I19: 0
B20: =VLOOKUP(A17&"3",Groups!$B$7:$D$65,3,0) -> Haiti | C20: 0 | E20: =VLOOKUP(D17&"3",Groups!$B$7:$D$65,3,0) -> IR Iran | F20: 0 | H20: =VLOOKUP(G17&"3",Groups!$B$7:$D$65,3,0) -> Uzbekistan | I20: 0
B21: =VLOOKUP(A17&"4",Groups!$B$7:$D$65,3,0) -> Scotland | C21: 0 | E21: =VLOOKUP(D17&"4",Groups!$B$7:$D$65,3,0) -> New Zealand | F21: 0 | H21: =VLOOKUP(G17&"4",Groups!$B$7:$D$65,3,0) -> Colombia | I21: 0
A23: D | B23: =Language!$E$130&" "&A23 -> Group D | C23: =Language!$E$174 -> Rating | D23: H | E23: =Language!$E$130&" "&D23 -> Group H | F23: =Language!$E$174 -> Rating | G23: L | H23: =Language!$E$130&" "&G23 -> Group L | I23: =Language!$E$174 -> Rating
B24: =VLOOKUP(A23&"1",Groups!$B$7:$D$65,3,0) -> USA | C24: 0 | E24: =VLOOKUP(D23&"1",Groups!$B$7:$D$65,3,0) -> Spain | F24: 0 | H24: =VLOOKUP(G23&"1",Groups!$B$7:$D$65,3,0) -> England | I24: 0
B25: =VLOOKUP(A23&"2",Groups!$B$7:$D$65,3,0) -> Paraguay | C25: 0 | E25: =VLOOKUP(D23&"2",Groups!$B$7:$D$65,3,0) -> Cape Verde | F25: 0 | H25: =VLOOKUP(G23&"2",Groups!$B$7:$D$65,3,0) -> Croatia | I25: 0
B26: =VLOOKUP(A23&"3",Groups!$B$7:$D$65,3,0) -> Australia | C26: 0 | E26: =VLOOKUP(D23&"3",Groups!$B$7:$D$65,3,0) -> Saudi Arabia | F26: 0 | H26: =VLOOKUP(G23&"3",Groups!$B$7:$D$65,3,0) -> Ghana | I26: 0
B27: =VLOOKUP(A23&"4",Groups!$B$7:$D$65,3,0) -> Turkey | C27: 0 | E27: =VLOOKUP(D23&"4",Groups!$B$7:$D$65,3,0) -> Uruguay | F27: 0 | H27: =VLOOKUP(G23&"4",Groups!$B$7:$D$65,3,0) -> Panama | I27: 0

Sheet HeadToHeadComp
D1: =Language!$E$122 -> Direct comparisons
D3: =Language!$E$140 -> Overall table | O3: =Language!$E$137 -> head-to-head record 1 | Z3: =Language!$E$138 -> head-to-head record 2 | AK3: =Language!$E$139 -> head-to-head record 3
D4: 7 | Z4: =IF(COUNTBLANK(CalcA!$BN$14:$BN$17)<4,Language!$E$136,"") | AK4: =IF(COUNTBLANK(CalcA!$BZ$14:$BZ$17)<4,Language!$E$136,"")
B5: A | E5: =Language!$E$131 -> Pts. | F5: =Language!$E$132 -> GD | G5: =Language!$E$133 -> Goals | J5: {=LEFT(CalcA!$H$21:$K$21,$D$4)} -> Mexico | K5: Czech R | L5: Rep. of | M5: South A | P5: =Language!$E$131 -> Pts. | Q5: =Language!$E$132 -> GD | R5: =Language!$E$133 -> Goals | U5: {=LEFT(CalcA!$BE$13:$BH$13,$D$4)} | AA5: =Language!$E$131 -> Pts. | AB5: =Language!$E$132 -> GD | AC5: =Language!$E$133 -> Goals | AF5: {=IF(COUNTBLANK(CalcA!$AZ$22:$AZ$25)<4,LEFT(CalcA!$BE$21:$BH$21,$D$4),LEFT(CalcA!$BS$13:$BV$13,$D$4))} | AL5: =Language!$E$131 -> Pts. | AM5: =Language!$E$132 -> GD | AN5: =Language!$E$133 -> Goals | AQ5: {=LEFT(CalcA!$CE$13:$CH$13,$D$4)} | AV5: =Language!$E$123 -> Fair play | AW5: =Language!$E$186 -> FIFA Rank
B6: {=IF(CalcA!$M$22:$M$25,"•","")} | D6: {=CalcA!$D$22:$D$25} -> Mexico | E6: {=CalcA!$E$22:$E$25} -> 9 | F6: =G6-I6 -> 5 | G6: {=CalcA!$F$22:$F$25} -> 6 | H6: =Language!$E$197 -> - | I6: {=CalcA!$G$22:$G$25} -> 1 | J6: {=CalcA!$H$22:$K$25} | K6: 1 - 0 | L6: 3 - 1 | M6: 2 - 0 | O6: {=CalcA!$AZ$14:$AZ$17} | P6: {=CalcA!$BA$14:$BA$17} | Q6: {=CalcA!$BB$14:$BB$17} | R6: {=CalcA!$BC$14:$BC$17} | S6: =Language!$E$197 -> - | T6: =IF(O6="","",R6-Q6) | U6: {=CalcA!$BE$14:$BH$17} | Z6: {=IF(COUNTBLANK(CalcA!$AZ$22:$AZ$25)<4,CalcA!$AZ$22:$AZ$25,CalcA!$BN$14:$BN$17)} | AA6: {=IF(COUNTBLANK(CalcA!$AZ$22:$AZ$25)<4,CalcA!$BA$22:$BA$25,CalcA!$BO$14:$BO$17)} | AB6: {=IF(COUNTBLANK(CalcA!$AZ$22:$AZ$25)<4,CalcA!$BB$22:$BB$25,CalcA!$BP$14:$BP$17)} | AC6: {=IF(COUNTBLANK(CalcA!$AZ$22:$AZ$25)<4,CalcA!$BC$22:$BC$25,CalcA!$BQ$14:$BQ$17)} | AD6: =Language!$E$197 -> - | AE6: =IF(Z6="","",AC6-AB6) | AF6: {=IF(COUNTBLANK(CalcA!$AZ$22:$AZ$25)<4,CalcA!$BE$22:$BH$25,CalcA!$BS$14:$BV$17)} | AK6: {=CalcA!$BZ$14:$BZ$17} | AL6: {=CalcA!$CA$14:$CA$17} | AM6: {=CalcA!$CB$14:$CB$17} | AN6: {=CalcA!$CC$14:$CC$17} | AO6: =Language!$E$197 -> - | AP6: =IF(AK6="","",AN6-AM6) | AQ6: {=CalcA!$CE$14:$CH$17} | AV6: {=VLOOKUP($D$6:$D$9,CalcA!$D$5:$P$8,13,0)} -> 0 | AW6: {=VLOOKUP($D$6:$D$9,CalcA!$D$5:$Q$8,14,0)} -> 15
D7: Czech Rep. | E7: 4 | F7: =G7-I7 -> 0 | G7: 2 | H7: =Language!$E$197 -> - | I7: 2 | J7: 0 - 1 | L7: 1 - 1 | M7: 1 - 0 | S7: =Language!$E$197 -> - | T7: =IF(O7="","",R7-Q7) | AD7: =Language!$E$197 -> - | AE7: =IF(Z7="","",AC7-AB7) | AO7: =Language!$E$197 -> - | AP7: =IF(AK7="","",AN7-AM7) | AV7: 0 | AW7: 41
D8: Rep. of Korea | E8: 2 | F8: =G8-I8 -> -2 | G8: 2 | H8: =Language!$E$197 -> - | I8: 4 | J8: 1 - 3 | K8: 1 - 1 | M8: 0 - 0 | S8: =Language!$E$197 -> - | T8: =IF(O8="","",R8-Q8) | AD8: =Language!$E$197 -> - | AE8: =IF(Z8="","",AC8-AB8) | AO8: =Language!$E$197 -> - | AP8: =IF(AK8="","",AN8-AM8) | AV8: 0 | AW8: 25
D9: South Africa | E9: 1 | F9: =G9-I9 -> -3 | G9: 0 | H9: =Language!$E$197 -> - | I9: 3 | J9: 0 - 2 | K9: 0 - 1 | L9: 0 - 0 | S9: =Language!$E$197 -> - | T9: =IF(O9="","",R9-Q9) | AD9: =Language!$E$197 -> - | AE9: =IF(Z9="","",AC9-AB9) | AO9: =Language!$E$197 -> - | AP9: =IF(AK9="","",AN9-AM9) | AV9: 0 | AW9: 60
Z12: =IF(COUNTBLANK(CalcB!$BN$14:$BN$17)<4,Language!$E$136,"") | AK12: =IF(COUNTBLANK(CalcB!$BZ$14:$BZ$17)<4,Language!$E$136,"")
B13: B | E13: =Language!$E$131 -> Pts. | F13: =Language!$E$132 -> GD | G13: =Language!$E$133 -> Goals | J13: {=LEFT(CalcB!$H$21:$K$21,$D$4)} -> Switzer | K13: Canada | L13: Qatar | M13: Bosnia/ | P13: =Language!$E$131 -> Pts. | Q13: =Language!$E$132 -> GD | R13: =Language!$E$133 -> Goals | U13: {=LEFT(CalcB!$BE$13:$BH$13,$D$4)} | AA13: =Language!$E$131 -> Pts. | AB13: =Language!$E$132 -> GD | AC13: =Language!$E$133 -> Goals | AF13: {=IF(COUNTBLANK(CalcB!$AZ$22:$AZ$25)<4,LEFT(CalcB!$BE$21:$BH$21,$D$4),LEFT(CalcB!$BS$13:$BV$13,$D$4))} | AL13: =Language!$E$131 -> Pts. | AM13: =Language!$E$132 -> GD | AN13: =Language!$E$133 -> Goals | AQ13: {=LEFT(CalcB!$CE$13:$CH$13,$D$4)} | AV13: =Language!$E$123 -> Fair play | AW13: =Language!$E$186 -> FIFA Rank
